<?xml version="1.0"?>
<!-- A minimal differential-drive robot with a depth camera, fully self-contained
     so project 07 does not depend on TurtleBot3. It publishes:
       /cmd_vel                       (subscribed, diff drive)
       /odom + odom->base_link TF     (diff drive plugin)
       /depth_camera/depth/image_raw  (32FC1 depth, metres)
       /depth_camera/image_raw        (rgb)
       /depth_camera/camera_info
     Gazebo Classic plugins: libgazebo_ros_diff_drive.so, libgazebo_ros_camera.so -->
<sdf version="1.6">
  <model name="depth_bot">
    <pose>0 0 0.1 0 0 0</pose>

    <link name="base_link">
      <inertial>
        <mass>5.0</mass>
        <inertia><ixx>0.05</ixx><iyy>0.05</iyy><izz>0.08</izz>
                 <ixy>0</ixy><ixz>0</ixz><iyz>0</iyz></inertia>
      </inertial>
      <collision name="c"><geometry><box><size>0.3 0.2 0.1</size></box></geometry></collision>
      <visual name="v">
        <geometry><box><size>0.3 0.2 0.1</size></box></geometry>
        <material><script><uri>file://media/materials/scripts/gazebo.material</uri><name>Gazebo/Blue</name></script></material>
      </visual>

      <!-- Depth camera mounted at the front -->
      <sensor name="depth_camera" type="depth">
        <pose>0.16 0 0.05 0 0 0</pose>
        <update_rate>20</update_rate>
        <camera>
          <horizontal_fov>1.047</horizontal_fov>
          <image><width>640</width><height>480</height><format>R8G8B8</format></image>
          <clip><near>0.1</near><far>10.0</far></clip>
        </camera>
        <plugin name="depth_cam" filename="libgazebo_ros_camera.so">
          <ros><namespace>depth_camera</namespace></ros>
          <camera_name>depth_camera</camera_name>
          <frame_name>depth_camera_optical_frame</frame_name>
          <min_depth>0.1</min_depth>
          <max_depth>10.0</max_depth>
        </plugin>
      </sensor>
    </link>

    <link name="left_wheel">
      <pose>-0.05 0.12 -0.03 -1.5708 0 0</pose>
      <inertial><mass>0.3</mass>
        <inertia><ixx>0.001</ixx><iyy>0.001</iyy><izz>0.001</izz>
                 <ixy>0</ixy><ixz>0</ixz><iyz>0</iyz></inertia></inertial>
      <collision name="c"><geometry><cylinder><radius>0.07</radius><length>0.04</length></cylinder></geometry></collision>
      <visual name="v"><geometry><cylinder><radius>0.07</radius><length>0.04</length></cylinder></geometry>
        <material><script><name>Gazebo/Black</name></script></material></visual>
    </link>
    <link name="right_wheel">
      <pose>-0.05 -0.12 -0.03 -1.5708 0 0</pose>
      <inertial><mass>0.3</mass>
        <inertia><ixx>0.001</ixx><iyy>0.001</iyy><izz>0.001</izz>
                 <ixy>0</ixy><ixz>0</ixz><iyz>0</iyz></inertia></inertial>
      <collision name="c"><geometry><cylinder><radius>0.07</radius><length>0.04</length></cylinder></geometry></collision>
      <visual name="v"><geometry><cylinder><radius>0.07</radius><length>0.04</length></cylinder></geometry>
        <material><script><name>Gazebo/Black</name></script></material></visual>
    </link>
    <link name="caster">
      <pose>0.12 0 -0.06 0 0 0</pose>
      <inertial><mass>0.1</mass>
        <inertia><ixx>0.0001</ixx><iyy>0.0001</iyy><izz>0.0001</izz>
                 <ixy>0</ixy><ixz>0</ixz><iyz>0</iyz></inertia></inertial>
      <collision name="c"><geometry><sphere><radius>0.04</radius></sphere></geometry>
        <surface><friction><ode><mu>0.0</mu><mu2>0.0</mu2></ode></friction></surface></collision>
      <visual name="v"><geometry><sphere><radius>0.04</radius></sphere></geometry></visual>
    </link>

    <joint name="left_wheel_joint" type="revolute">
      <parent>base_link</parent><child>left_wheel</child>
      <axis><xyz>0 0 1</xyz></axis>
    </joint>
    <joint name="right_wheel_joint" type="revolute">
      <parent>base_link</parent><child>right_wheel</child>
      <axis><xyz>0 0 1</xyz></axis>
    </joint>
    <joint name="caster_joint" type="ball">
      <parent>base_link</parent><child>caster</child>
    </joint>

    <plugin name="diff_drive" filename="libgazebo_ros_diff_drive.so">
      <ros></ros>
      <left_joint>left_wheel_joint</left_joint>
      <right_joint>right_wheel_joint</right_joint>
      <wheel_separation>0.24</wheel_separation>
      <wheel_diameter>0.14</wheel_diameter>
      <max_wheel_torque>10</max_wheel_torque>
      <command_topic>cmd_vel</command_topic>
      <odometry_topic>odom</odometry_topic>
      <odometry_frame>odom</odometry_frame>
      <robot_base_frame>base_link</robot_base_frame>
      <publish_odom>true</publish_odom>
      <publish_odom_tf>true</publish_odom_tf>
      <publish_wheel_tf>true</publish_wheel_tf>
    </plugin>
  </model>
</sdf>
